#VRML_SIM R2023b utf8

EXTERNPROTO "https://raw.githubusercontent.com/cyberbotics/webots/R2023b/projects/appearances/protos/BrushedSteel.proto"
EXTERNPROTO "https://raw.githubusercontent.com/cyberbotics/webots/R2023b/projects/appearances/protos/Copper.proto"
EXTERNPROTO "https://raw.githubusercontent.com/cyberbotics/webots/R2023b/projects/appearances/protos/DamascusSteel.proto"
EXTERNPROTO "https://raw.githubusercontent.com/cyberbotics/webots/R2023b/projects/appearances/protos/HammeredCopper.proto"
EXTERNPROTO "https://raw.githubusercontent.com/cyberbotics/webots/R2023b/projects/appearances/protos/SandyGround.proto"
EXTERNPROTO "https://raw.githubusercontent.com/cyberbotics/webots/R2023b/projects/appearances/protos/SolarCell.proto"
EXTERNPROTO "https://raw.githubusercontent.com/cyberbotics/webots/R2023b/projects/objects/backgrounds/protos/TexturedBackground.proto"
EXTERNPROTO "https://raw.githubusercontent.com/cyberbotics/webots/R2023b/projects/objects/backgrounds/protos/TexturedBackgroundLight.proto"
EXTERNPROTO "https://raw.githubusercontent.com/cyberbotics/webots/R2023b/projects/objects/floors/protos/UnevenTerrain.proto"
EXTERNPROTO "https://raw.githubusercontent.com/cyberbotics/webots/R2023b/projects/appearances/protos/ReflectiveSurface.proto"
EXTERNPROTO "https://raw.githubusercontent.com/cyberbotics/webots/R2023b/projects/appearances/protos/DryMud.proto"

WorldInfo {
}
Viewpoint {
  orientation 0.09021796315285954 0.2543128606197434 -0.9629048177509302 0.9452244388873344
  position -1.8771578201770869 20.010955773307884 6.363931065834523
}
TexturedBackground {
  texture "mars"
}
TexturedBackgroundLight {
  luminosity 2
}
UnevenTerrain {
  translation 0 0 -0.97
  appearance SandyGround {
    colorOverride 0.5 0.5 0.4
    textureTransform TextureTransform {
      scale 50 50
    }
  }
}
Robot {
  translation 4.009916326678551 12.589612466949951 2.5960650040637834
  rotation -0.02710798049916727 -0.04009156324242593 -0.9988282254472165 1.9657091060682554
  children [
    DEF ds2 DistanceSensor {
      translation -0.35 0.15 0
      rotation 0 0 1 2.68
      children [
        Shape {
          appearance ReflectiveSurface {
          }
          geometry Box {
            size 0.05 0.05 0.05
          }
        }
      ]
      name "ds2"
      physics Physics {
        mass 1
      }
      lookupTable [
        0 0 0
        1 1000 0
      ]
    }
    DEF ds1 DistanceSensor {
      translation -0.350387 -0.169997 0
      rotation 0 0 1 -2.5
      children [
        Shape {
          appearance ReflectiveSurface {
          }
          geometry Box {
            size 0.05 0.05 0.05
          }
        }
      ]
      name "ds1(1)"
      physics Physics {
        mass 1
      }
    }
    DEF body Shape {
      appearance HammeredCopper {
      }
      geometry Box {
        size 0.7 0.5 0.2
      }
    }
    Solid {
      translation 0 0 0.19
      children [
        DEF panel Shape {
          appearance SolarCell {
          }
          geometry Box {
            size 0.8 0.5 0.01
          }
        }
        Solid {
          translation 0.3 -0.19 -0.05
          children [
            Shape {
              appearance Copper {
              }
              geometry Cylinder {
                height 0.1
                radius 0.02
              }
            }
          ]
          name "solar_panel_support1"
        }
        Solid {
          translation 0.3 0.19 -0.05
          children [
            Shape {
              appearance Copper {
              }
              geometry Cylinder {
                height 0.1
                radius 0.02
              }
            }
          ]
          name "solar_panel_support2"
        }
        Solid {
          translation -0.3 0.19 -0.05
          children [
            Shape {
              appearance Copper {
              }
              geometry Cylinder {
                height 0.1
                radius 0.02
              }
            }
          ]
          name "solar_panel_support3"
        }
        Solid {
          translation -0.3 -0.19 -0.05
          children [
            Shape {
              appearance Copper {
              }
              geometry Cylinder {
                height 0.1
                radius 0.02
              }
            }
          ]
          name "solar_panel_support4"
        }
      ]
      name "solar_panel"
    }
    Solid {
      translation -0.18 -0.24 0
      children [
        SliderJoint {
          jointParameters JointParameters {
            position -0.0003566301755397763
            minStop -0.1
            staticFriction 1
          }
          device [
            LinearMotor {
              name "linear1_left"
              maxForce 50
            }
          ]
          endPoint Solid {
            translation -0.0008377778007950809 -0.01836137353058831 0.05971022778960332
            rotation 0.9999999921226456 -9.457187858035381e-05 8.252798602959777e-05 -1.5708919962625085
            children [
              DEF cylinder1 Shape {
                appearance DamascusSteel {
                }
                geometry Cylinder {
                  height 0.09
                  radius 0.02
                }
              }
              Solid {
                translation 0 0 -0.05
                children [
                  DEF sphere1 Shape {
                    appearance BrushedSteel {
                    }
                    geometry Sphere {
                      radius 0.02
                    }
                  }
                  Solid {
                    translation 0 0.1 1.79608e-07
                    rotation -1 0 0 -1.5707953071795862
                    children [
                      DEF cylinder2 Shape {
                        appearance BrushedSteel {
                        }
                        geometry Cylinder {
                          height 0.2
                          radius 0.02
                        }
                      }
                      Solid {
                        translation 0 0 -0.11
                        children [
                          DEF sphere1 Shape {
                            appearance BrushedSteel {
                            }
                            geometry Sphere {
                              radius 0.02
                            }
                          }
                          Solid {
                            translation 0 -0.03 -9.99999e-08
                            rotation 1 0 0 1.5708
                            children [
                              DEF cylinder3 Shape {
                                appearance BrushedSteel {
                                }
                                geometry Cylinder {
                                  height 0.06
                                  radius 0.02
                                }
                              }
                              HingeJoint {
                                jointParameters HingeJointParameters {
                                  position 433.8027718200608
                                  axis 0 0 1
                                  anchor -9.51224e-05 0.00113507 0.0800056
                                }
                                device [
                                  RotationalMotor {
                                    name "wheel1_left"
                                  }
                                ]
                                endPoint Solid {
                                  translation 0.0004408437796992969 0.00011411771824162238 0.08000499999999995
                                  rotation -7.579237705443309e-07 5.58548462739139e-06 -0.9999999999841139 6.02019855152895
                                  children [
                                    DEF wheel Shape {
                                      appearance DamascusSteel {
                                      }
                                      geometry Cylinder {
                                        height 0.15
                                        radius 0.15
                                      }
                                    }
                                  ]
                                  boundingObject USE wheel
                                  physics Physics {
                                    mass 1
                                  }
                                  linearVelocity -1.626828120535606e-06 3.139579131884316e-05 -1.6382435429135744e-06
                                  angularVelocity -8.549828293623718e-06 3.973288033437686e-06 -4.6581596439984566e-07
                                }
                              }
                            ]
                            boundingObject USE cylinder3
                            physics DEF phy1 Physics {
                              mass 1
                            }
                          }
                        ]
                        name "solid(1)"
                        boundingObject USE sphere1
                        physics USE phy1
                      }
                    ]
                    boundingObject USE cylinder2
                    physics USE phy1
                  }
                ]
                boundingObject USE sphere1
                physics USE phy1
              }
            ]
            boundingObject USE cylinder1
            physics USE phy1
            linearVelocity -5.804106101152203e-07 3.091852832417885e-05 -2.5683459725769285e-06
            angularVelocity -7.217381648456927e-07 5.531048466919117e-07 -1.9468667313594578e-07
          }
        }
      ]
      name "wheel1_left_system"
      physics USE phy1
    }
    Solid {
      translation 0.18 -0.24 0
      children [
        SliderJoint {
          jointParameters JointParameters {
            position -8.093964275907495e-05
            minStop -0.1
            staticFriction 1
          }
          device [
            LinearMotor {
              name "linear2_left"
              maxForce 50
            }
          ]
          endPoint Solid {
            translation 0.0003296970703097202 -0.018183464481857925 0.05996747752247866
            rotation 0.9999999936435989 -7.896499135999216e-05 8.048187641525716e-05 -1.5708383718751984
            children [
              DEF cylinder1 Shape {
                appearance DamascusSteel {
                }
                geometry Cylinder {
                  height 0.09
                  radius 0.02
                }
              }
              Solid {
                translation 0 0 -0.05
                children [
                  DEF sphere1 Shape {
                    appearance BrushedSteel {
                    }
                    geometry Sphere {
                      radius 0.02
                    }
                  }
                  Solid {
                    translation 0 0.1 1.79608e-07
                    rotation -1 0 0 -1.5707953071795862
                    children [
                      DEF cylinder2 Shape {
                        appearance BrushedSteel {
                        }
                        geometry Cylinder {
                          height 0.2
                          radius 0.02
                        }
                      }
                      Solid {
                        translation 0 0 -0.11
                        children [
                          DEF sphere1 Shape {
                            appearance BrushedSteel {
                            }
                            geometry Sphere {
                              radius 0.02
                            }
                          }
                          Solid {
                            translation 0 -0.03 -9.99999e-08
                            rotation 1 0 0 1.5708
                            children [
                              DEF cylinder3 Shape {
                                appearance BrushedSteel {
                                }
                                geometry Cylinder {
                                  height 0.06
                                  radius 0.02
                                }
                              }
                              HingeJoint {
                                jointParameters HingeJointParameters {
                                  position 439.03412745416244
                                  axis 0 0 1
                                  anchor 0.000341778 0.000558794 0.0800055
                                }
                                device [
                                  RotationalMotor {
                                    name "wheel2_left"
                                  }
                                ]
                                endPoint Solid {
                                  translation -0.00017789597407383008 0.00030310227998810743 0.08000499999999995
                                  rotation -7.364255069768883e-07 -1.78624788180947e-06 -0.9999999999981334 0.788842912227684
                                  children [
                                    DEF wheel Shape {
                                      appearance DamascusSteel {
                                      }
                                      geometry Cylinder {
                                        height 0.15
                                        radius 0.15
                                      }
                                    }
                                  ]
                                  boundingObject USE wheel
                                  physics Physics {
                                    mass 1
                                  }
                                  linearVelocity -7.815938016797449e-07 3.0276282229965814e-05 -1.4948970210184742e-06
                                  angularVelocity -7.930096016139516e-06 3.3909749207445397e-06 -4.3592565142236113e-07
                                }
                              }
                            ]
                            boundingObject USE cylinder3
                            physics DEF phy1 Physics {
                              mass 1
                            }
                          }
                        ]
                        name "solid(1)"
                        boundingObject USE sphere1
                        physics USE phy1
                      }
                    ]
                    boundingObject USE cylinder2
                    physics USE phy1
                  }
                ]
                boundingObject USE sphere1
                physics USE phy1
              }
            ]
            boundingObject USE cylinder1
            physics USE phy1
            linearVelocity -1.8283942682018793e-07 3.038839859846547e-05 -2.2407921250305617e-06
            angularVelocity -9.224172380345736e-07 4.027972998070165e-07 -2.0178987282751926e-07
          }
        }
      ]
      name "wheel2_left_system"
      physics USE phy1
    }
    Solid {
      translation 0.18 0.24 0
      rotation 0 0 1 3.14159
      children [
        SliderJoint {
          jointParameters JointParameters {
            position -4.7036470464495935e-05
            minStop -0.1
            staticFriction 1
          }
          device [
            LinearMotor {
              name "linear2_right"
              maxForce 50
            }
          ]
          endPoint Solid {
            translation -0.0008276469833603528 -0.018374509159130525 0.060018948791186744
            rotation -0.9999999922623781 9.245038766788978e-05 -8.323562813952379e-05 1.5708906026112013
            children [
              DEF cylinder1 Shape {
                appearance DamascusSteel {
                }
                geometry Cylinder {
                  height 0.09
                  radius 0.02
                }
              }
              Solid {
                translation 0 0 -0.05
                children [
                  DEF sphere1 Shape {
                    appearance BrushedSteel {
                    }
                    geometry Sphere {
                      radius 0.02
                    }
                  }
                  Solid {
                    translation 0 0.1 1.79608e-07
                    rotation -1 0 0 -1.5707953071795862
                    children [
                      DEF cylinder2 Shape {
                        appearance BrushedSteel {
                        }
                        geometry Cylinder {
                          height 0.2
                          radius 0.02
                        }
                      }
                      Solid {
                        translation 0 0 -0.11
                        children [
                          DEF sphere1 Shape {
                            appearance BrushedSteel {
                            }
                            geometry Sphere {
                              radius 0.02
                            }
                          }
                          Solid {
                            translation 0 -0.03 -9.99999e-08
                            rotation 1 0 0 1.5708
                            children [
                              DEF cylinder3 Shape {
                                appearance BrushedSteel {
                                }
                                geometry Cylinder {
                                  height 0.06
                                  radius 0.02
                                }
                              }
                              HingeJoint {
                                jointParameters HingeJointParameters {
                                  position -298.95080752824595
                                  axis 0 0 1
                                  anchor 0.00034353 0.000611995 0.0800044
                                }
                                device [
                                  RotationalMotor {
                                    name "wheel2_right"
                                  }
                                ]
                                endPoint Solid {
                                  translation 0.0007956697920961601 0.0010511925564239085 0.08000499999999995
                                  rotation -0.9689735779515042 0.24716432839346789 1.2908937436130033e-06 3.1415920387322176
                                  children [
                                    DEF wheel Shape {
                                      appearance DamascusSteel {
                                      }
                                      geometry Cylinder {
                                        height 0.15
                                        radius 0.15
                                      }
                                    }
                                  ]
                                  boundingObject USE wheel
                                  physics Physics {
                                    mass 1
                                  }
                                  linearVelocity 8.358040227629481e-07 3.0227401709495926e-05 -1.6960060029873504e-06
                                  angularVelocity -8.23229772280729e-06 3.0268591430024758e-06 -3.6811544499746286e-07
                                }
                              }
                            ]
                            boundingObject USE cylinder3
                            physics DEF phy1 Physics {
                              mass 1
                            }
                          }
                        ]
                        name "solid(1)"
                        boundingObject USE sphere1
                        physics USE phy1
                      }
                    ]
                    boundingObject USE cylinder2
                    physics USE phy1
                  }
                ]
                boundingObject USE sphere1
                physics USE phy1
              }
            ]
            boundingObject USE cylinder1
            physics USE phy1
            linearVelocity 6.114108969107765e-07 3.0346519567112292e-05 -2.2167158103002167e-06
            angularVelocity -9.335192672974148e-07 4.041044304239657e-08 -1.294147655910079e-07
          }
        }
      ]
      name "wheel2_right_system"
      physics USE phy1
    }
    Solid {
      translation -0.18 0.24 0
      rotation 0 0 1 3.14159
      children [
        SliderJoint {
          jointParameters JointParameters {
            position -0.0008101606438645454
            minStop -0.1
            staticFriction 1
          }
          device [
            LinearMotor {
              name "linear1_right"
              maxForce 50
            }
          ]
          endPoint Solid {
            translation 0.00031154623387408265 -0.018172465909291446 0.05923801912497973
            rotation -0.9999999932420197 8.484106517047719e-05 -7.948555944300578e-05 1.5708422396011763
            children [
              DEF cylinder1 Shape {
                appearance DamascusSteel {
                }
                geometry Cylinder {
                  height 0.09
                  radius 0.02
                }
              }
              Solid {
                translation 0 0 -0.05
                children [
                  DEF sphere1 Shape {
                    appearance BrushedSteel {
                    }
                    geometry Sphere {
                      radius 0.02
                    }
                  }
                  Solid {
                    translation 0 0.1 1.79608e-07
                    rotation -1 0 0 -1.5707953071795862
                    children [
                      DEF cylinder2 Shape {
                        appearance BrushedSteel {
                        }
                        geometry Cylinder {
                          height 0.2
                          radius 0.02
                        }
                      }
                      Solid {
                        translation 0 0 -0.11
                        children [
                          DEF sphere1 Shape {
                            appearance BrushedSteel {
                            }
                            geometry Sphere {
                              radius 0.02
                            }
                          }
                          Solid {
                            translation 0 -0.03 -9.99999e-08
                            rotation 1 0 0 1.5708
                            children [
                              DEF cylinder3 Shape {
                                appearance BrushedSteel {
                                }
                                geometry Cylinder {
                                  height 0.06
                                  radius 0.02
                                }
                              }
                              HingeJoint {
                                jointParameters HingeJointParameters {
                                  position -75.20478776428246
                                  axis 0 0 1
                                  anchor 0.00034338 0.000576422 0.0800045
                                }
                                device [
                                  RotationalMotor {
                                    name "wheel1_right"
                                  }
                                ]
                                endPoint Solid {
                                  translation 0.00026938665592288245 -1.5373443631877494e-05 0.08000499999999995
                                  rotation -0.09656792086285819 0.9953263970478203 1.7217677245436167e-07 3.141590022438019
                                  children [
                                    DEF wheel Shape {
                                      appearance DamascusSteel {
                                      }
                                      geometry Cylinder {
                                        height 0.15
                                        radius 0.15
                                      }
                                    }
                                  ]
                                  boundingObject USE wheel
                                  physics Physics {
                                    mass 1
                                  }
                                  linearVelocity 3.132781180642752e-06 2.9083745980454278e-05 -1.0015857859003842e-06
                                  angularVelocity -8.717153571395214e-06 2.4732945307367454e-06 -4.352872237909537e-07
                                }
                              }
                            ]
                            boundingObject USE cylinder3
                            physics DEF phy1 Physics {
                              mass 1
                            }
                          }
                        ]
                        name "solid(1)"
                        boundingObject USE sphere1
                        physics USE phy1
                      }
                    ]
                    boundingObject USE cylinder2
                    physics USE phy1
                  }
                ]
                boundingObject USE sphere1
                physics USE phy1
              }
            ]
            boundingObject USE cylinder1
            physics USE phy1
            linearVelocity 1.7841086822684819e-06 2.9723664403997e-05 -2.2739049484243945e-06
            angularVelocity -1.1460432089527219e-06 -4.295467648940623e-07 -2.0244997757867521e-07
          }
        }
      ]
      name "wheel1_right_system"
      physics USE phy1
    }
  ]
  boundingObject USE body
  physics DEF phy Physics {
    mass 1
  }
  controller "robot_controller"
  linearVelocity 4.311845455716939e-07 3.0391830888339025e-05 -2.572960710300075e-06
  angularVelocity -9.226485012350288e-07 1.4006093802041353e-07 -1.8561115469454162e-07
}
DEF solid2 Solid {
  translation 16.798264958792497 15.097309065996622 3.3222339301679154
  rotation -0.0724456164766711 -0.003367366117202344 0.9973666795611069 0.9255808023873542
  children [
    DEF box_shape Shape {
      appearance DryMud {
      }
      geometry Box {
        size 0.8 1.7 2
      }
    }
  ]
  name "solid2"
  boundingObject USE box_shape
  physics USE phy1
  linearVelocity -8.724635977318899e-07 1.250657603903244e-06 -9.52510076386225e-08
  angularVelocity 2.2622818647577323e-08 -2.231916857016062e-08 -8.861682417065984e-08
}
DEF solid3 Solid {
  translation 9.259492283657885 3.8625517769745326 3.6549409176390375
  rotation 0.5065155432232317 0.5957083453721954 0.623356697026025 2.230083583634153
  children [
    DEF box_shape Shape {
      appearance DryMud {
      }
      geometry Box {
        size 1.8 1.8 1.8
      }
    }
  ]
  name "solid3"
  boundingObject USE box_shape
  physics USE phy1
  linearVelocity -3.526638464107239e-07 -1.0860671950176955e-06 -4.597132276099216e-08
  angularVelocity 9.941460508322702e-10 -1.0850552373159935e-08 2.8320025895499744e-07
}
DEF solid4 Solid {
  translation 13.678471168056728 7.997994044430386 3.6625679236425475
  rotation 0.480577208572934 0.6363756866900082 0.6033834038072868 2.2112032661173395
  children [
    DEF sphere_shape Shape {
      appearance DryMud {
      }
      geometry Sphere {
      }
    }
  ]
  name "solid4"
  boundingObject USE box_shape
  physics USE phy1
  linearVelocity 5.480534698813152e-07 2.0788473895029463e-06 -1.0421829594108946e-07
  angularVelocity -1.4758033911790147e-09 5.676302953375656e-08 1.0988186365840186e-06
}
DEF solid1 Solid {
  translation 3.092082085110401 6.459064335986476 3.4672689385554496
  rotation 0.29950304124820504 0.6771746327782184 0.6721104410770309 2.512512688665028
  children [
    DEF box_shape Shape {
      appearance DryMud {
      }
      geometry Box {
        size 0.8 1.7 2
      }
    }
  ]
  name "solid1"
  boundingObject USE box_shape
  physics USE phy1
  linearVelocity -6.336501799012736e-07 2.923361518140762e-07 -2.7896896862549888e-08
  angularVelocity 6.3488036524889564e-09 1.82820192713521e-08 4.0811867953198895e-07
}
